## Explication

L'objectif de cet exercice est de montrer comment gérer les exceptions à l'intérieur d'un thread pour éviter que le programme principal ne s'arrête de manière inattendue. Les threads sont souvent utilisés pour exécuter des tâches en parallèle, mais ils nécessitent une gestion soigneuse des exceptions pour maintenir la stabilité du programme.

## Code Attendu

Le code fourni crée un thread qui exécute une tâche pouvant potentiellement générer une exception. L'utilisation de try et except au sein de la fonction risky_task assure que toute exception levée pendant l'exécution du thread est capturée et gérée de manière appropriée, permettant ainsi au thread de se terminer proprement sans affecter les autres parties du programme.

```python
import threading
import time

def risky_task():
    try:
        for i in range(5):
            print(f"Exécution de la tâche {i}")
            time.sleep(1)
            if i == 2:
                raise Exception("Une erreur s'est produite dans le thread!")
    except Exception as e:
        print(f"Exception capturée dans le thread: {e}")

# Créer et démarrer un thread
thread = threading.Thread(target=risky_task)
thread.start()
thread.join()
print("Thread terminé")
```

## Résultat Attendu

Le script doit afficher les messages de progression jusqu'à ce que l'exception soit déclenchée, puis afficher le message d'erreur capturée, et enfin confirmer que le thread a été terminé proprement.

```arduino
Exécution de la tâche 0
Exécution de la tâche 1
Exécution de la tâche 2
Exception capturée dans le thread: Une erreur s'est produite dans le thread!
Thread terminé
```